Workbook

Sheet backlog
C1: jour | I1: 1 | J1: 2 | K1: 3 | L1: 4 | M1: 5 | N1: 6 | O1: 7 | P1: 8 | Q1: 9 | R1: 10 | S1: 11 | T1: 12 | U1: 13 | V1: 14 | W1: 15 | X1: 16 | Y1: 17 | Z1: 18 | AA1: 19 | AB1: 20 | AC1: 21
C2: Sommaire effort restant | I2: =J10 -> 170 | J2: =L10 -> 165 | K2: =N10 -> 162 | L2: =P10 -> 158 | M2: =R10 -> 158 | N2: =T10 -> 147 | O2: =V10 -> 147 | P2: =X10 -> 144 | Q2: =Z10 -> 139 | R2: =AB10 -> 135 | S2: =AD10 -> 131 | T2: =AF10 -> 126 | U2: =AH10 -> 121 | V2: =AJ10 -> 112 | W2: =AL10 -> 103 | X2: =AN10 -> 90 | Y2: =AP10 -> 90 | Z2: =AR10 -> 83 | AA2: =AT10 -> 74 | AB2: =AV10 -> 71 | AC2: =AX10 -> 42 | AD2: =AZ10 -> 33
C3: Sommaire efforts dépensé | I3: =K10 -> 9 | J3: =M10 -> 6 | K3: =O10 -> 4 | L3: =Q10 -> 4 | M3: =S10 -> 12 | N3: =U10 -> 6 | O3: =W10 -> 11 | P3: =Y10 -> 13 | Q3: =AA10 -> 8 | R3: =AC10 -> 4 | S3: =AE10 -> 10 | T3: =AG10 -> 9 | U3: =AI10 -> 9 | V3: =AK10 -> 15 | W3: =AM10 -> 14 | X3: =AO10 -> 12 | Y3: =AQ10 -> 11 | Z3: =AS10 -> 13 | AA3: =AU10 -> 13 | AB3: =AW10 -> 29 | AC3: =AY10 -> 0 | AD3: =BA10 -> 0 | AH3: =SUM(I3:AD3) -> 212
C6: Sprint 1 : Mettre en place les fonctionnalités de base pour l’authentification, la gestion du profil, des cours, des échéances, du calendrier et des notifications d’un système académique et financier.
B8: Numéro item product backlog | D8: Équipe | I8: jours du sprint / (effort restant estimé en début de journée | heures travaillées ce jour) | BB8: Total pour tâche | BC8: Total pour tâche par membre équipe
C9: Cas d'utilisation ou user-story/tâche | I9: 0 | J9: =I9+1 -> 1 | L9: =J9+1 -> 2 | N9: =L9+1 -> 3 | P9: =N9+1 -> 4 | R9: =P9+1 -> 5 | T9: =R9+1 -> 6 | V9: =T9+1 -> 7 | X9: =V9+1 -> 8 | Z9: =X9+1 -> 9 | AB9: =Z9+1 -> 10 | AD9: =AB9+1 -> 11 | AF9: =AD9+1 -> 12 | AH9: =AF9+1 -> 13 | AJ9: =AH9+1 -> 14 | AL9: =AJ9+1 -> 15 | AN9: =AL9+1 -> 16 | AP9: =AN9+1 -> 17 | AR9: =AP9+1 -> 18 | AT9: =AR9+1 -> 19 | AV9: =AT9+1 -> 20 | AX9: 21 | AZ9: =AX9+1 -> 22 | BC9: =D10 -> Oryna | BD9: =F10 -> Romuald | BE9: =G10 -> Kenny | BF9: =E10 -> Aziz | BG9: =H10 -> Joana
D10: =team!D2 -> Oryna | E10: =team!D3 -> Aziz | F10: =team!D6 -> Romuald | G10: =team!D5 -> Kenny | H10: =team!D4 -> Joana | I10: =SUM(I11:I519) -> 176 | J10: =SUM(J11:J519) -> 170 | K10: =SUM(K11:K519) -> 9 | L10: =SUM(L11:L519) -> 165 | M10: =SUM(M11:M519) -> 6 | N10: =SUM(N11:N519) -> 162 | O10: =SUM(O11:O519) -> 4 | P10: =SUM(P11:P519) -> 158 | ... AX10: =SUM(AX11:AX519) -> 42 | AZ10: =SUM(AZ11:AZ519) -> 33 | BB10: =SUM(BB11:BB519) -> 233 | BC10: =SUM(BC11:BC519) -> 56 | BD10: =SUM(BD11:BD519) -> 69 | BE10: =SUM(BE11:BE519) -> 41 | BF10: =SUM(BF11:BF519) -> 43 | BG10: =SUM(BG11:BG519) -> 24
B11: 1 | C11: Authentification utilisateur | D11: 1
C12: Création de la page de connexion | D12: 1 | E12: 0 | F12: 0 | G12: 0 | H12: 0 | I12: 8 | J12: =I12 -> 8 | K12: 2 | L12: =J12-K12 -> 6 | M12: 1 | N12: =L12-M12 -> 5 | O12: 0 | P12: =N12-O12 -> 5 | Q12: 0 | R12: =P12-Q12 -> 5 | S12: 1 | T12: =R12-S12 -> 4 | U12: 0 | V12: =T12-U12 -> 4 | W12: 0 | X12: =V12-W12 -> 4 | Y12: 1 | Z12: =X12-Y12 -> 3 | AA12: 0 | AB12: =Z12-AA12 -> 3 | AC12: 1 | AD12: =AB12-AC12 -> 2 | AE12: 1 | AF12: =AD12-AE12 -> 1 | AG12: 0 | AH12: =AF12-AG12 -> 1 | AI12: 1 | AJ12: =AH12-AI12 -> 0 | AK12: 0 | AL12: =AJ12-AK12 -> 0 | AM12: 0 | AN12: =AL12-AM12 -> 0 | AO12: 0 | AP12: =AN12-AO12 -> 0 | AQ12: 0 | AR12: =AP12-AQ12 -> 0 | AS12: 0 | AT12: =AR12-AS12 -> 0 | AU12: 0 | AV12: =AT12-AU12 -> 0 | AW12: 0 | AX12: =AV12-AW12 -> 0 | AY12: 0 | AZ12: =AX12-AY12 -> 0 | BB12: =AY12+AW12+AU12+AS12+AQ12+AO12+AM12+AK12+AI12+AG12+AE12+AC12+AA12+Y12+W12+U12+S12+Q12+O12+M12+K12 -> 8 | BC12: =BB12*D12 -> 8 | BD12: =BC12*F12 -> 0 | BE12: =BD12*G12 -> 0 | BF12: =BB12*E12 -> 0 | BG12: =BB12*H12 -> 0
C13: Creation de la page d'inscription | D13: 1 | E13: 0 | F13: 0 | G13: 0 | H13: =1-D13-E13 -> 0 | I13: 8 | J13: =I13 -> 8 | K13: 0 | L13: =J13-K13 -> 8 | M13: 0 | N13: =L13-M13 -> 8 | O13: 0 | P13: =N13-O13 -> 8 | Q13: 0 | R13: =P13-Q13 -> 8 | S13: 0 | T13: =R13-S13 -> 8 | U13: 0 | V13: =T13-U13 -> 8 | W13: 0 | X13: =V13-W13 -> 8 | Y13: 0 | Z13: =X13-Y13 -> 8 | AA13: 0 | AB13: =Z13-AA13 -> 8 | AC13: 0 | AD13: =AB13-AC13 -> 8 | AE13: 1 | AF13: =AD13-AE13 -> 7 | AG13: 2 | AH13: =AF13-AG13 -> 5 | AI13: 1 | AJ13: =AH13-AI13 -> 4 | AK13: 3 | AL13: =AJ13-AK13 -> 1 | AM13: 0 | AN13: =AL13-AM13 -> 1 | AO13: 0 | AP13: =AN13-AO13 -> 1 | AQ13: 1 | AR13: =AP13-AQ13 -> 0 | AS13: 0 | AT13: =AR13-AS13 -> 0 | AU13: 0 | AV13: =AT13-AU13 -> 0 | AW13: 0 | AX13: =AV13-AW13 -> 0 | AY13: 0 | AZ13: =AX13-AY13 -> 0 | BB13: =AY13+AW13+AU13+AS13+AQ13+AO13+AM13+AK13+AI13+AG13+AE13+AC13+AA13+Y13+W13+U13+S13+Q13+O13+M13+K13 -> 8 | BC13: =$BB13*D13 -> 8 | BD13: =BC13*F13 -> 0 | BE13: =BD13*G13 -> 0 | BF13: =$BB13*E13 -> 0 | BG13: =$BB13*H13 -> 0
C14: Validation | D14: 1 | E14: 0 | F14: 0 | G14: 0 | H14: =1-D14-E14 -> 0 | I14: 2 | J14: =I14 -> 2 | K14: 0 | L14: =J14-K14 -> 2 | M14: 0 | N14: =L14-M14 -> 2 | O14: 0 | P14: =N14-O14 -> 2 | Q14: 0 | R14: =P14-Q14 -> 2 | S14: 0 | T14: =R14-S14 -> 2 | V14: =T14-U14 -> 2 | X14: =V14-W14 -> 2 | Z14: =X14-Y14 -> 2 | AB14: =Z14-AA14 -> 2 | AD14: =AB14-AC14 -> 2 | AF14: =AD14-AE14 -> 2 | AH14: =AF14-AG14 -> 2 | AJ14: =AH14-AI14 -> 2 | AK14: 2 | AL14: 3 | AM14: 1 | AN14: =AL14-AM14 -> 2 | AO14: 0 | AP14: =AN14-AO14 -> 2 | AQ14: 2 | AR14: 4 | AS14: 2 | AT14: =AR14-AS14 -> 2 | AU14: 0 | AV14: =AT14-AU14 -> 2 | AW14: 0 | AX14: =AV14-AW14 -> 2 | AY14: 2 | AZ14: =AX14-AY14 -> 0 | BB14: =AY14+AW14+AU14+AS14+AQ14+AO14+AM14+AK14+AI14+AG14+AE14+AC14+AA14+Y14+W14+U14+S14+Q14+O14+M14+K14 -> 9 | BC14: =$BB14*D14 -> 9 | BD14: =BC14*F14 -> 0 | BE14: =BD14*G14 -> 0 | BF14: =$BB14*E14 -> 0 | BG14: =$BB14*H14 -> 0
C15: Setup de Xcode | D15: 1 | E15: 0 | F15: 0 | G15: 0 | H15: =1-D15-E15 -> 0 | I15: 5 | J15: =I15 -> 5 | K15: 0 | L15: =J15-K15 -> 5 | M15: 0 | N15: =L15-M15 -> 5 | O15: 0 | P15: =N15-O15 -> 5 | Q15: 0 | R15: =P15-Q15 -> 5 | S15: 0 | T15: =R15-S15 -> 5 | U15: 0 | V15: =T15-U15 -> 5 | W15: 0 | X15: =V15-W15 -> 5 | Y15: 0 | Z15: =X15-Y15 -> 5 | AA15: 0 | AB15: =Z15-AA15 -> 5 | AC15: 0 | AD15: =AB15-AC15 -> 5 | AE15: 0 | AF15: =AD15-AE15 -> 5 | AG15: 0 | AH15: =AF15-AG15 -> 5 | AI15: 0 | AJ15: =AH15-AI15 -> 5 | AK15: 3 | AL15: =AJ15-AK15 -> 2 | AM15: 2 | AN15: =AL15-AM15 -> 0 | AO15: 0 | AP15: =AN15-AO15 -> 0 | AQ15: 0 | AR15: =AP15-AQ15 -> 0 | AS15: 0 | AT15: =AR15-AS15 -> 0 | AU15: 0 | AV15: =AT15-AU15 -> 0 | AW15: 0 | AX15: =AV15-AW15 -> 0 | AY15: 0 | AZ15: =AX15-AY15 -> 0 | BB15: =AY15+AW15+AU15+AS15+AQ15+AO15+AM15+AK15+AI15+AG15+AE15+AC15+AA15+Y15+W15+U15+S15+Q15+O15+M15+K15 -> 5 | BC15: =$BB15*D15 -> 5 | BD15: =BC15*F15 -> 0 | BE15: =BD15*G15 -> 0 | BF15: =$BB15*E15 -> 0 | BG15: =$BB15*H15 -> 0
B16: 2 | C16: Création du profil d'utilisateur | D16: 1
C17: Création de la page principal pour afficher les options pour utilisateur | D17: 1 | E17: 0 | F17: 0 | G17: 0 | H17: =1-D17-E17 -> 0 | I17: 6 | J17: =I17 -> 6 | K17: 0 | L17: =J17-K17 -> 6 | M17: 0 | N17: =L17-M17 -> 6 | O17: 0 | P17: =N17-O17 -> 6 | Q17: 0 | R17: =P17-Q17 -> 6 | S17: 0 | T17: =R17-S17 -> 6 | U17: 0 | V17: =T17-U17 -> 6 | W17: 0 | X17: =V17-W17 -> 6 | Y17: 0 | Z17: =X17-Y17 -> 6 | AA17: 0 | AB17: =Z17-AA17 -> 6 | AC17: 0 | AD17: =AB17-AC17 -> 6 | AE17: 0 | AF17: =AD17-AE17 -> 6 | AG17: 0 | AH17: =AF17-AG17 -> 6 | AI17: 0 | AJ17: =AH17-AI17 -> 6 | AK17: 0 | AL17: =AJ17-AK17 -> 6 | AM17: 0 | AN17: =AL17-AM17 -> 6 | AO17: 0 | AP17: =AN17-AO17 -> 6 | AQ17: 0 | AR17: =AP17-AQ17 -> 6 | AS17: 0 | AT17: =AR17-AS17 -> 6 | AU17: 0 | AV17: =AT17-AU17 -> 6 | AW17: 0 | AX17: =AV17-AW17 -> 6 | AY17: 0 | AZ17: =AX17-AY17 -> 6 | BB17: 5 | BC17: =$BB17*D17 -> 5 | BD17: =BC17*F17 -> 0 | BE17: =BD17*G17 -> 0 | BF17: =$BB17*E17 -> 0 | BG17: =$BB17*H17 -> 0
C18: Ajouter la possiblité de faire les changements dans le dossier (ex:ajouter image profil, dark mode, profile details) | D18: 1 | E18: 0 | F18: 0 | G18: 0 | H18: =1-D18-E18 -> 0 | I18: 6 | J18: =I18 -> 6 | K18: 0 | L18: =J18-K18 -> 6 | M18: 0 | N18: =L18-M18 -> 6 | O18: 0 | P18: =N18-O18 -> 6 | Q18: 0 | R18: =P18-Q18 -> 6 | S18: 0 | T18: =R18-S18 -> 6 | U18: 0 | V18: =T18-U18 -> 6 | W18: 0 | X18: =V18-W18 -> 6 | Y18: 0 | Z18: =X18-Y18 -> 6 | AA18: 0 | AB18: =Z18-AA18 -> 6 | AC18: 0 | AD18: =AB18-AC18 -> 6 | AE18: 0 | AF18: =AD18-AE18 -> 6 | AG18: 0 | AH18: =AF18-AG18 -> 6 | AI18: 0 | AJ18: =AH18-AI18 -> 6 | AK18: 0 | AL18: =AJ18-AK18 -> 6 | AM18: 0 | AN18: =AL18-AM18 -> 6 | AO18: 0 | AP18: =AN18-AO18 -> 6 | AQ18: 0 | AR18: =AP18-AQ18 -> 6 | AS18: 0 | AT18: =AR18-AS18 -> 6 | AU18: 0 | AV18: =AT18-AU18 -> 6 | AW18: 0 | AX18: =AV18-AW18 -> 6 | AY18: 0 | AZ18: =AX18-AY18 -> 6 | BB18: 4 | BC18: =$BB18*D18 -> 4 | BD18: =BC18*F18 -> 0 | BE18: =BD18*G18 -> 0 | BF18: =$BB18*E18 -> 0 | BG18: =$BB18*H18 -> 0
C19: Visualisation du menu pour utilisauter | D19: 1 | E19: 0 | F19: 0 | G19: 0 | H19: =1-D19-E19 -> 0 | I19: 4 | J19: =I19 -> 4 | K19: 0 | L19: =J19-K19 -> 4 | M19: 0 | N19: =L19-M19 -> 4 | O19: 0 | P19: =N19-O19 -> 4 | Q19: 0 | R19: =P19-Q19 -> 4 | S19: 0 | T19: =R19-S19 -> 4 | U19: 0 | V19: =T19-U19 -> 4 | W19: 0 | X19: =V19-W19 -> 4 | Y19: 0 | Z19: =X19-Y19 -> 4 | AA19: 0 | AB19: =Z19-AA19 -> 4 | AC19: 0 | AD19: =AB19-AC19 -> 4 | AE19: 0 | AF19: =AD19-AE19 -> 4 | AG19: 0 | AH19: =AF19-AG19 -> 4 | AI19: 0 | AJ19: =AH19-AI19 -> 4 | AK19: 0 | AL19: =AJ19-AK19 -> 4 | AM19: 0 | AN19: =AL19-AM19 -> 4 | AO19: 0 | AP19: =AN19-AO19 -> 4 | AQ19: 0 | AR19: =AP19-AQ19 -> 4 | AS19: 0 | AT19: =AR19-AS19 -> 4 | AU19: 0 | AV19: =AT19-AU19 -> 4 | AW19: 0 | AX19: =AV19-AW19 -> 4 | AY19: 0 | AZ19: =AX19-AY19 -> 4 | BB19: 3 | BC19: =$BB19*D19 -> 3 | BD19: =BC19*F19 -> 0 | BE19: =BD19*G19 -> 0 | BF19: =$BB19*E19 -> 0 | BG19: =$BB19*H19 -> 0
C20: Creation de la base de données pour sauvegarder les information personnels | D20: 1 | E20: 0 | F20: 0 | G20: 0 | H20: =1-D20-E20 -> 0 | I20: 8 | J20: =I20 -> 8 | K20: 0 | L20: =J20-K20 -> 8 | M20: 0 | N20: =L20-M20 -> 8 | O20: 0 | P20: =N20-O20 -> 8 | Q20: 0 | R20: =P20-Q20 -> 8 | S20: 0 | T20: =R20-S20 -> 8 | U20: 0 | V20: =T20-U20 -> 8 | W20: 0 | X20: =V20-W20 -> 8 | Y20: 0 | Z20: =X20-Y20 -> 8 | AA20: 0 | AB20: =Z20-AA20 -> 8 | AC20: 0 | AD20: =AB20-AC20 -> 8 | AE20: 0 | AF20: =AD20-AE20 -> 8 | AG20: 0 | AH20: =AF20-AG20 -> 8 | AI20: 4 | AJ20: =AH20-AI20 -> 4 | AK20: 0 | AL20: =AJ20-AK20 -> 4 | AM20: 0 | AN20: =AL20-AM20 -> 4 | AO20: 4 | AP20: =AN20-AO20 -> 0 | AQ20: 0 | AR20: =AP20-AQ20 -> 0 | AS20: 0 | AT20: =AR20-AS20 -> 0 | AU20: 0 | AV20: =AT20-AU20 -> 0 | AW20: 0 | AX20: =AV20-AW20 -> 0 | AY20: 0 | AZ20: =AX20-AY20 -> 0 | BB20: =AY20+AW20+AU20+AS20+AQ20+AO20+AM20+AK20+AI20+AG20+AE20+AC20+AA20+Y20+W20+U20+S20+Q20+O20+M20+K20 -> 8 | BC20: =$BB20*D20 -> 8 | BD20: =BC20*F20 -> 0 | BE20: =BD20*G20 -> 0 | BF20: =$BB20*E20 -> 0 | BG20: =$BB20*H20 -> 0
B21: 3 | C21: Gestion du cours (ajout) | H21: 1
C22: Ajouter cours (code, nom) | D22: 0 | E22: 0 | F22: 0 | G22: 0 | H22: 1 | I22: 7 | J22: =I22 -> 7 | K22: 0 | L22: =J22-K22 -> 7 | M22: 0 | N22: =L22-M22 -> 7 | O22: 0 | P22: =N22-O22 -> 7 | Q22: 0 | R22: =P22-Q22 -> 7 | S22: 0 | T22: =R22-S22 -> 7 | U22: 0 | V22: =T22-U22 -> 7 | W22: 0 | X22: =V22-W22 -> 7 | Y22: 1 | Z22: =X22-Y22 -> 6 | AA22: 0 | AB22: =Z22-AA22 -> 6 | AC22: 0 | AD22: =AB22-AC22 -> 6 | AE22: 1 | AF22: =AD22-AE22 -> 5 | AG22: 3 | AH22: =AF22-AG22 -> 2 | AI22: 0 | AJ22: =AH22-AI22 -> 2 | AK22: 2 | AL22: =AJ22-AK22 -> 0 | AM22: 0 | AN22: =AL22-AM22 -> 0 | AO22: 0 | AP22: 2 | AQ22: 1 | AR22: =AP22-AQ22 -> 1 | AS22: 0 | AT22: =AR22-AS22 -> 1 | AU22: 1 | AV22: =AT22-AU22 -> 0 | AX22: =AV22-AW22 -> 0 | AZ22: =AX22-AY22 -> 0 | BB22: =AY22+AW22+AU22+AS22+AQ22+AO22+AM22+AK22+AI22+AG22+AE22+AC22+AA22+Y22+W22+U22+S22+Q22+O22+M22+K22 -> 9 | BC22: =$BB22*D22 -> 0 | BD22: =BC22*F22 -> 0 | BE22: =BD22*G22 -> 0 | BF22: =$BB22*E22 -> 0 | BG22: =$BB22*H22 -> 9
C23: Sauvegarder le cours | D23: 0 | E23: 0 | F23: 0 | G23: 0 | H23: 1 | I23: 3 | J23: =I23 -> 3 | K23: 0 | L23: =J23-K23 -> 3 | M23: 0 | N23: =L23-M23 -> 3 | O23: 0 | P23: =N23-O23 -> 3 | Q23: 0 | R23: =P23-Q23 -> 3 | S23: 0 | T23: =R23-S23 -> 3 | U23: 0 | V23: =T23-U23 -> 3 | W23: 0 | X23: =V23-W23 -> 3 | Y23: 0 | Z23: =X23-Y23 -> 3 | AA23: 0 | AB23: =Z23-AA23 -> 3 | AC23: 0 | AD23: =AB23-AC23 -> 3 | AE23: 0 | AF23: =AD23-AE23 -> 3 | AG23: 0 | AH23: =AF23-AG23 -> 3 | AI23: 1 | AJ23: =AH23-AI23 -> 2 | AK23: 0 | AL23: =AJ23-AK23 -> 2 | AM23: 0 | AN23: =AL23-AM23 -> 2 | AO23: 0 | AP23: =AN23-AO23 -> 2 | AQ23: 1 | AR23: =AP23-AQ23 -> 1 | AS23: 0 | AT23: =AR23-AS23 -> 1 | AU23: 0 | AV23: 1 | AW23: 1 | AX23: =AV23-AW23 -> 0 | AY23: 0 | AZ23: 0 | BB23: =AY23+AW23+AU23+AS23+AQ23+AO23+AM23+AK23+AI23+AG23+AE23+AC23+AA23+Y23+W23+U23+S23+Q23+O23+M23+K23 -> 3 | BC23: 0 | BD23: 0 | BE23: 0 | BF23: 0 | BG23: =$BB23*H23 -> 3
C24: Afficher la liste des cours après ajout | D24: 0 | E24: 0 | F24: 0 | G24: 0 | H24: 1 | I24: 4 | J24: 0 | K24: 0 | L24: 0 | M24: 0 | N24: 0 | O24: 0 | P24: 0 | Q24: 0 | R24: 0 | S24: 0 | T24: 0 | U24: 0 | V24: 0 | W24: 0 | X24: 0 | Y24: 0 | Z24: 0 | AA24: 0 | AB24: 0 | AC24: 0 | AD24: 0 | AE24: 0 | AF24: 0 | AG24: 0 | AH24: 0 | AI24: 0 | AJ24: 0 | AK24: 0 | AL24: 0 | AM24: 0 | AN24: 0 | AO24: 1 | AP24: 3 | AQ24: 1 | AR24: 2 | AS24: 0 | AT24: 2 | AU24: 0 | AV24: 2 | AW24: 2 | AX24: 0 | AY24: 0 | AZ24: 0 | BB24: =AY24+AW24+AU24+AS24+AQ24+AO24+AM24+AK24+AI24+AG24+AE24+AC24+AA24+Y24+W24+U24+S24+Q24+O24+M24+K24 -> 4 | BC24: 0 | BD24: 0 | BE24: 0 | BF24: 0 | BG24: =$BB24*H24 -> 4
B25: pour sprint2 | C25: (Souhaité) Trier les cours selon le nombre d’évaluations ou l’évaluation la plus proche (sera fait quand les échéances seront prêtes) | D25: 0 | E25: 0 | F25: 0 | G25: 0 | H25: 1 | I25: 5 | J25: =I25 -> 5 | K25: 0 | L25: =J25-K25 -> 5 | M25: 0 | N25: =L25-M25 -> 5 | O25: 0 | P25: =N25-O25 -> 5 | Q25: 0 | R25: =P25-Q25 -> 5 | S25: 0 | T25: =R25-S25 -> 5 | U25: 0 | V25: =T25-U25 -> 5 | W25: 0 | X25: =V25-W25 -> 5 | Z25: =X25-Y25 -> 5 | AB25: =Z25-AA25 -> 5 | AD25: =AB25-AC25 -> 5 | AF25: =AD25-AE25 -> 5 | AH25: =AF25-AG25 -> 5 | AJ25: =AH25-AI25 -> 5 | AL25: =AJ25-AK25 -> 5 | AN25: =AL25-AM25 -> 5 | AP25: =AN25-AO25 -> 5 | AR25: =AP25-AQ25 -> 5 | AT25: =AR25-AS25 -> 5 | AV25: =AT25-AU25 -> 5 | AX25: =AV25-AW25 -> 5 | AZ25: =AX25-AY25 -> 5 | BB25: =AY25+AW25+AU25+AS25+AQ25+AO25+AM25+AK25+AI25+AG25+AE25+AC25+AA25+Y25+W25+U25+S25+Q25+O25+M25+K25 -> 0 | BC25: =$BB25*D25 -> 0 | BD25: =BC25*F25 -> 0 | BE25: =BD25*G25 -> 0 | BF25: =$BB25*E25 -> 0 | BG25: =$BB25*H25 -> 0
B26: 4 | C26: Gestion du seuil du passage | H26: 1
C27: Attribuer un pourcentage de passage à un cours | D27: 0 | E27: 0 | F27: 0 | G27: 0 | H27: 1 | I27: 2 | J27: =I27 -> 2 | K27: 0 | L27: =J27-K27 -> 2 | M27: 0 | N27: =L27-M27 -> 2 | O27: 0 | P27: =N27-O27 -> 2 | Q27: 0 | R27: =P27-Q27 -> 2 | S27: 0 | T27: =R27-S27 -> 2 | U27: 0 | V27: =T27-U27 -> 2 | W27: 0 | X27: =V27-W27 -> 2 | Y27: 0 | Z27: =X27-Y27 -> 2 | AA27: 0 | AB27: =Z27-AA27 -> 2 | AC27: 0 | AD27: =AB27-AC27 -> 2 | AE27: 0 | AF27: =AD27-AE27 -> 2 | AG27: 0 | AH27: =AF27-AG27 -> 2 | AI27: 0 | AJ27: =AH27-AI27 -> 2 | AK27: 0 | AL27: =AJ27-AK27 -> 2 | AM27: 2 | AN27: =AL27-AM27 -> 0 | AO27: 0 | AP27: =AN27-AO27 -> 0 | AQ27: 0 | AR27: =AP27-AQ27 -> 0 | AS27: 0 | AT27: =AR27-AS27 -> 0 | AU27: 0 | AV27: 2 | AW27: 2 | AX27: =AV27-AW27 -> 0 | AZ27: =AX27-AY27 -> 0 | BB27: =AY27+AW27+AU27+AS27+AQ27+AO27+AM27+AK27+AI27+AG27+AE27+AC27+AA27+Y27+W27+U27+S27+Q27+O27+M27+K27 -> 4 | BC27: =$BB27*D27 -> 0 | BD27: =BC27*F27 -> 0 | BE27: =BD27*G27 -> 0 | BF27: =$BB27*E27 -> 0 | BG27: =$BB27*H27 -> 4
B28: pour sprint2 | C28: Calculer automatiquement le minimum requis pour passer le cours selon les notes déjà obtenues. | D28: 0 | E28: 0 | F28: 0 | G28: 0 | H28: 1 | I28: 5 | J28: =I28 -> 5 | K28: 0 | L28: =J28-K28 -> 5 | M28: 0 | N28: =L28-M28 -> 5 | O28: 0 | P28: =N28-O28 -> 5 | Q28: 0 | R28: =P28-Q28 -> 5 | S28: 0 | T28: =R28-S28 -> 5 | U28: 0 | V28: =T28-U28 -> 5 | W28: 0 | X28: =V28-W28 -> 5 | Z28: =X28-Y28 -> 5 | AB28: =Z28-AA28 -> 5 | AD28: =AB28-AC28 -> 5 | AF28: =AD28-AE28 -> 5 | AH28: =AF28-AG28 -> 5 | AJ28: =AH28-AI28 -> 5 | AL28: =AJ28-AK28 -> 5 | AN28: =AL28-AM28 -> 5 | AP28: =AN28-AO28 -> 5 | AR28: =AP28-AQ28 -> 5 | AT28: =AR28-AS28 -> 5 | AV28: =AT28-AU28 -> 5 | AX28: =AV28-AW28 -> 5 | AZ28: =AX28-AY28 -> 5 | BB28: =AY28+AW28+AU28+AS28+AQ28+AO28+AM28+AK28+AI28+AG28+AE28+AC28+AA28+Y28+W28+U28+S28+Q28+O28+M28+K28 -> 0 | BC28: =$BB28*D28 -> 0 | BD28: =BC28*F28 -> 0 | BE28: =BD28*G28 -> 0 | BF28: =$BB28*E28 -> 0 | BG28: =$BB28*H28 -> 0
B29: 5 | C29: Gestion du cours(suppression ou modification) | H29: 1 | BD29: =BC29*F29 -> 0 | BE29: =BD29*G29 -> 0
C30: Modifier un cours existant | D30: 0 | E30: 0 | F30: 0 | G30: 0 | H30: 1 | I30: 3 | J30: =I30 -> 3 | K30: 0 | L30: =J30-K30 -> 3 | M30: 0 | N30: =L30-M30 -> 3 | O30: 0 | P30: =N30-O30 -> 3 | Q30: 0 | R30: =P30-Q30 -> 3 | S30: 0 | T30: =R30-S30 -> 3 | U30: 0 | V30: =T30-U30 -> 3 | W30: 0 | X30: =V30-W30 -> 3 | Y30: 0 | Z30: =X30-Y30 -> 3 | AA30: 0 | AB30: =Z30-AA30 -> 3 | AC30: 0 | AD30: =AB30-AC30 -> 3 | AE30: 0 | AF30: =AD30-AE30 -> 3 | AG30: 0 | AH30: =AF30-AG30 -> 3 | AI30: 0 | AJ30: =AH30-AI30 -> 3 | AK30: 0 | AL30: =AJ30-AK30 -> 3 | AM30: 0 | AN30: =AL30-AM30 -> 3 | AO30: 0 | AP30: =AN30-AO30 -> 3 | AQ30: 0 | AR30: =AP30-AQ30 -> 3 | AS30: 2 | AT30: 0 | AV30: =AT30-AU30 -> 0 | AX30: =AV30-AW30 -> 0 | AZ30: =AX30-AY30 -> 0 | BB30: =AY30+AW30+AU30+AS30+AQ30+AO30+AM30+AK30+AI30+AG30+AE30+AC30+AA30+Y30+W30+U30+S30+Q30+O30+M30+K30 -> 2 | BC30: =$BB30*D30 -> 0 | BD30: =BC30*F30 -> 0 | BE30: =BD30*G30 -> 0 | BF30: =$BB30*E30 -> 0 | BG30: =$BB30*H30 -> 2
C31: Supprimer un cours (ex. abandonné) | D31: 0 | E31: 0 | F31: 0 | G31: 0 | H31: 1 | I31: 3 | J31: =I31 -> 3 | K31: 0 | L31: =J31-K31 -> 3 | M31: 0 | N31: =L31-M31 -> 3 | O31: 0 | P31: =N31-O31 -> 3 | Q31: 0 | R31: =P31-Q31 -> 3 | S31: 0 | T31: =R31-S31 -> 3 | U31: 0 | V31: =T31-U31 -> 3 | W31: 0 | X31: =V31-W31 -> 3 | Y31: 0 | Z31: =X31-Y31 -> 3 | AA31: 0 | AB31: =Z31-AA31 -> 3 | AC31: 0 | AD31: =AB31-AC31 -> 3 | AE31: 0 | AF31: =AD31-AE31 -> 3 | AG31: 0 | AH31: =AF31-AG31 -> 3 | AI31: 0 | AJ31: =AH31-AI31 -> 3 | AK31: 0 | AL31: =AJ31-AK31 -> 3 | AM31: 0 | AN31: =AL31-AM31 -> 3 | AO31: 0 | AP31: =AN31-AO31 -> 3 | AQ31: 0 | AR31: =AP31-AQ31 -> 3 | AS31: 0 | AT31: =AR31-AS31 -> 3 | AU31: 2 | AV31: 0 | AX31: =AV31-AW31 -> 0 | AZ31: =AX31-AY31 -> 0 | BB31: =AY31+AW31+AU31+AS31+AQ31+AO31+AM31+AK31+AI31+AG31+AE31+AC31+AA31+Y31+W31+U31+S31+Q31+O31+M31+K31 -> 2 | BC31: =$BB31*D31 -> 0 | BD31: =BC31*F31 -> 0 | BE31: =BD31*G31 -> 0 | BF31: =$BB31*E31 -> 0 | BG31: =$BB31*H31 -> 2
B32: 6 | C32: Ajout des échéances | G32: 1
C33: Connexion à la bd via API supabase | D33: 0 | E33: 0 | F33: 0 | G33: 1 | H33: 0 | I33: 5 | J33: =I33 -> 5 | K33: 0 | L33: =J33-K33 -> 5 | M33: 0 | N33: =L33-M33 -> 5 | O33: 0 | P33: =N33-O33 -> 5 | Q33: 0 | R33: =P33-Q33 -> 5 | S33: 4 | T33: 0 | U33: 0 | V33: =T33-U33 -> 0 | W33: 0 | X33: =V33-W33 -> 0 | Y33: 1 | Z33: 0 | AA33: 0 | AB33: 0 | AC33: 0 | AD33: =AB33-AC33 -> 0 | AE33: 0 | AF33: =AD33-AE33 -> 0 | AG33: 0 | AH33: =AF33-AG33 -> 0 | AI33: 0 | AJ33: =AH33-AI33 -> 0 | AK33: 0 | AL33: =AJ33-AK33 -> 0 | AM33: 0 | AN33: =AL33-AM33 -> 0 | AO33: 0 | AP33: =AN33-AO33 -> 0 | AQ33: 0 | AR33: =AP33-AQ33 -> 0 | AS33: 0 | AT33: =AR33-AS33 -> 0 | AU33: 0 | AV33: =AT33-AU33 -> 0 | AW33: 0 | AX33: =AV33-AW33 -> 0 | AY33: 0 | AZ33: =AX33-AY33 -> 0 | BB33: =AY33+AW33+AU33+AS33+AQ33+AO33+AM33+AK33+AI33+AG33+AE33+AC33+AA33+Y33+W33+U33+S33+Q33+O33+M33+K33 -> 5 | BC33: =$BB33*D33 -> 0 | BD33: =BC33*F33 -> 0 | BE33: =$BB33*G33 -> 5 | BF33: =$BB33*E33 -> 0 | BG33: =$BB33*H33 -> 0
C34: Setup de Android studio | D34: 0 | E34: 0 | F34: 0 | G34: 1 | H34: 0 | I34: 3 | J34: 3 | K34: 0 | L34: 3 | M34: 0 | N34: 3 | O34: 0 | P34: 3 | Q34: 0 | R34: 3 | S34: 2 | T34: 1 | U34: 4 | V34: 0 | W34: 0 | X34: 0 | Y34: 0 | Z34: =X34-Y34 -> 0 | AA34: 0 | AB34: =Z34-AA34 -> 0 | AC34: 0 | AD34: =AB34-AC34 -> 0 | AE34: 0 | AF34: =AD34-AE34 -> 0 | AG34: 0 | AH34: =AF34-AG34 -> 0 | AI34: 0 | AJ34: =AH34-AI34 -> 0 | AK34: 0 | AL34: =AJ34-AK34 -> 0 | AM34: 0 | AN34: =AL34-AM34 -> 0 | AO34: 0 | AP34: =AN34-AO34 -> 0 | AQ34: 0 | AR34: =AP34-AQ34 -> 0 | AS34: 0 | AT34: =AR34-AS34 -> 0 | AU34: 0 | AV34: =AT34-AU34 -> 0 | AW34: 0 | AX34: =AV34-AW34 -> 0 | AY34: 0 | AZ34: =AX34-AY34 -> 0 | BB34: =AY34+AW34+AU34+AS34+AQ34+AO34+AM34+AK34+AI34+AG34+AE34+AC34+AA34+Y34+W34+U34+S34+Q34+O34+M34+K34 -> 6 | BC34: 0 | BD34: =BC34*F34 -> 0 | BE34: =$BB34*G34 -> 6 | BF34: 0 | BG34: 0
C35: Création de la page des échéances | D35: 0 | E35: 0 | F35: 0 | G35: 1 | H35: 0 | I35: 5 | J35: =I35 -> 5 | K35: 0 | L35: =J35-K35 -> 5 | M35: 0 | N35: =L35-M35 -> 5 | O35: 0 | P35: =N35-O35 -> 5 | Q35: 0 | R35: =P35-Q35 -> 5 | S35: 2 | T35: =R35-S35 -> 3 | U35: 0 | V35: =T35-U35 -> 3 | W35: 2 | X35: 3 | Y35: 2 | Z35: =X35-Y35 -> 1 | AA35: 1 | AB35: =Z35-AA35 -> 0 | AC35: 0 | AD35: 0 | AE35: 0 | AF35: =AD35-AE35 -> 0 | AG35: 0 | AH35: 0 | AI35: 0 | AJ35: =AH35-AI35 -> 0 | AK35: 0 | AL35: =AJ35-AK35 -> 0 | AM35: 0 | AN35: 0 | AO35: 0 | AP35: =AN35-AO35 -> 0 | AQ35: 0 | AR35: 0 | AS35: 0 | AT35: =AR35-AS35 -> 0 | AU35: 0 | AV35: =AT35-AU35 -> 0 | AW35: 0 | AX35: =AV35-AW35 -> 0 | AY35: 0 | AZ35: =AX35-AY35 -> 0 | BB35: =AY35+AW35+AU35+AS35+AQ35+AO35+AM35+AK35+AI35+AG35+AE35+AC35+AA35+Y35+W35+U35+S35+Q35+O35+M35+K35 -> 7 | BC35: =$BB35*D35 -> 0 | BD35: =BC35*F35 -> 0 | BE35: =$BB35*G35 -> 7 | BF35: =$BB35*E35 -> 0 | BG35: =$BB35*H35 -> 0
C36: Création de l'ajout des échéances | D36: 0 | E36: 0 | F36: 0 | G36: 1 | H36: 0 | I36: 8 | J36: =I36 -> 8 | K36: 0 | L36: =J36-K36 -> 8 | M36: 0 | N36: =L36-M36 -> 8 | O36: 0 | P36: =N36-O36 -> 8 | Q36: 0 | R36: =P36-Q36 -> 8 | S36: 2 | T36: =R36-S36 -> 6 | U36: 0 | V36: =T36-U36 -> 6 | W36: 3 | X36: =V36-W36 -> 3 | Y36: 2 | Z36: 3 | AA36: 1 | AB36: =Z36-AA36 -> 2 | AC36: 1 | AD36: =AB36-AC36 -> 1 | AE36: 1 | AF36: =AD36-AE36 -> 0 | AG36: 0 | AH36: =AF36-AG36 -> 0 | AI36: 0 | AJ36: =AH36-AI36 -> 0 | AK36: 0 | AL36: =AJ36-AK36 -> 0 | AM36: 0 | AN36: =AL36-AM36 -> 0 | AO36: 0 | AP36: =AN36-AO36 -> 0 | AQ36: 0 | AR36: =AP36-AQ36 -> 0 | AS36: 0 | AT36: =AR36-AS36 -> 0 | AU36: 0 | AV36: =AT36-AU36 -> 0 | AW36: 0 | AX36: =AV36-AW36 -> 0 | AY36: 0 | AZ36: =AX36-AY36 -> 0 | BB36: =AY36+AW36+AU36+AS36+AQ36+AO36+AM36+AK36+AI36+AG36+AE36+AC36+AA36+Y36+W36+U36+S36+Q36+O36+M36+K36 -> 10 | BC36: =$BB36*D36 -> 0 | BD36: =BC36*F36 -> 0 | BE36: =$BB36*G36 -> 10 | BF36: =$BB36*E36 -> 0 | BG36: =$BB36*H36 -> 0
B37: 7 | C37: Modification des échéances | G37: 1
C38: Ajout de modification des échéances | D38: 0 | E38: 0 | F38: 0 | G38: 1 | H38: 0 | I38: 6 | J38: =I38 -> 6 | K38: 0 | L38: =J38-K38 -> 6 | M38: 0 | N38: =L38-M38 -> 6 | O38: 0 | P38: =N38-O38 -> 6 | Q38: 0 | R38: =P38-Q38 -> 6 | S38: 0 | T38: =R38-S38 -> 6 | U38: 0 | V38: =T38-U38 -> 6 | W38: 0 | X38: =V38-W38 -> 6 | Y38: 0 | Z38: =X38-Y38 -> 6 | AA38: 0 | AB38: =Z38-AA38 -> 6 | AC38: 0 | AD38: =AB38-AC38 -> 6 | AE38: 0 | AF38: =AD38-AE38 -> 6 | AG38: 2 | AH38: =AF38-AG38 -> 4 | AI38: 0 | AJ38: =AH38-AI38 -> 4 | AK38: 1 | AL38: =AJ38-AK38 -> 3 | AM38: 2 | AN38: 2 | AO38: 1 | AP38: =AN38-AO38 -> 1 | AQ38: 1 | AR38: =AP38-AQ38 -> 0 | AS38: 0 | AT38: =AR38-AS38 -> 0 | AU38: 0 | AV38: =AT38-AU38 -> 0 | AW38: 0 | AX38: =AV38-AW38 -> 0 | AY38: 0 | AZ38: =AX38-AY38 -> 0 | BB38: =AY38+AW38+AU38+AS38+AQ38+AO38+AM38+AK38+AI38+AG38+AE38+AC38+AA38+Y38+W38+U38+S38+Q38+O38+M38+K38 -> 7 | BC38: =$BB38*D38 -> 0 | BD38: =BC38*F38 -> 0 | BE38: =$BB38*G38 -> 7 | BF38: =$BB38*E38 -> 0 | BG38: =$BB38*H38 -> 0
C39: Ajout de suppression des échéances | D39: 0 | E39: 0 | F39: 0 | G39: 1 | H39: 0 | I39: 6 | J39: =I39 -> 6 | K39: 0 | L39: =J39-K39 -> 6 | M39: 0 | N39: =L39-M39 -> 6 | O39: 0 | P39: =N39-O39 -> 6 | Q39: 0 | R39: =P39-Q39 -> 6 | S39: 0 | T39: =R39-S39 -> 6 | U39: 0 | V39: =T39-U39 -> 6 | W39: 0 | X39: =V39-W39 -> 6 | Y39: 0 | Z39: =X39-Y39 -> 6 | AA39: 0 | AB39: =Z39-AA39 -> 6 | AC39: 0 | AD39: =AB39-AC39 -> 6 | AE39: 0 | AF39: =AD39-AE39 -> 6 | AG39: 1 | AH39: =AF39-AG39 -> 5 | AI39: 0 | AJ39: =AH39-AI39 -> 5 | AK39: 1 | AL39: =AJ39-AK39 -> 4 | AM39: 1 | AN39: =AL39-AM39 -> 3 | AO39: 1 | AP39: =AN39-AO39 -> 2 | AQ39: 1 | AR39: =AP39-AQ39 -> 1 | AS39: 1 | AT39: =AR39-AS39 -> 0 | AU39: 0 | AV39: =AT39-AU39 -> 0 | AW39: 0 | AX39: =AV39-AW39 -> 0 | AY39: 0 | AZ39: =AX39-AY39 -> 0 | BB39: =AY39+AW39+AU39+AS39+AQ39+AO39+AM39+AK39+AI39+AG39+AE39+AC39+AA39+Y39+W39+U39+S39+Q39+O39+M39+K39 -> 6 | BC39: =$BB39*D39 -> 0 | BD39: =BC39*F39 -> 0 | BE39: =$BB39*G39 -> 6 | BF39: =$BB39*E39 -> 0 | BG39: =$BB39*H39 -> 0
B40: 8 | C40: Vue calendrier hebdomadaire : Affichage des examens, quiz, paiement à travers une globale du calendrier | D40: 0.25 | E40: 0.75
C41: Création du calendrier basique | D41: 0 | E41: 1 | F41: 0 | G41: 0 | H41: 0 | I41: 5 | J41: =I41 -> 5 | K41: 1 | L41: =J41-K41 -> 4 | M41: 0 | N41: =L41-M41 -> 4 | O41: 0 | P41: =N41-O41 -> 4 | Q41: 3 | R41: 5 | S41: 0 | T41: =R41-S41 -> 5 | U41: 0 | V41: =T41-U41 -> 5 | W41: 3 | X41: =V41-W41 -> 2 | Y41: 0 | Z41: =X41-Y41 -> 2 | AA41: 0 | AB41: =Z41-AA41 -> 2 | AC41: 0 | AD41: =AB41-AC41 -> 2 | AE41: 2 | AF41: 3 | AG41: 1 | AH41: =AF41-AG41 -> 2 | AI41: 0 | AJ41: =AH41-AI41 -> 2 | AK41: 0 | AL41: =AJ41-AK41 -> 2 | AM41: 0 | AN41: =AL41-AM41 -> 2 | AO41: 0 | AP41: =AN41-AO41 -> 2 | AQ41: 0 | AR41: =AP41-AQ41 -> 2 | AS41: 2 | AT41: 0 | AU41: 0 | AV41: =AT41-AU41 -> 0 | AW41: 0 | AX41: =AV41-AW41 -> 0 | AY41: 0 | AZ41: =AX41-AY41 -> 0 | BB41: =AY41+AW41+AU41+AS41+AQ41+AO41+AM41+AK41+AI41+AG41+AE41+AC41+AA41+Y41+W41+U41+S41+Q41+O41+M41+K41 -> 12 | BC41: =$BB41*D41 -> 0 | BD41: =BC41*F41 -> 0 | BE41: =BB41*G41 -> 0 | BF41: =$BB41*E41 -> 12 | BG41: =$BB41*H41 -> 0
C42: Ajout de la rubrique évènements à venir | D42: 0 | E42: 1 | F42: 0 | G42: 0 | H42: 0 | I42: 4 | J42: =I42 -> 4 | K42: 2 | L42: =J42-K42 -> 2 | M42: 0 | N42: =L42-M42 -> 2 | O42: 0 | P42: =N42-O42 -> 2 | Q42: 0 | R42: =P42-Q42 -> 2 | S42: 0 | T42: =R42-S42 -> 2 | U42: 0 | V42: =T42-U42 -> 2 | W42: 0 | X42: =V42-W42 -> 2 | Y42: 0 | Z42: =X42-Y42 -> 2 | AA42: 0 | AB42: =Z42-AA42 -> 2 | AC42: 0 | AD42: =AB42-AC42 -> 2 | AE42: 1 | AF42: =AD42-AE42 -> 1 | AG42: 0 | AH42: =AF42-AG42 -> 1 | AI42: 0 | AJ42: =AH42-AI42 -> 1 | AK42: 0 | AL42: =AJ42-AK42 -> 1 | AM42: 0 | AN42: =AL42-AM42 -> 1 | AO42: 1 | AP42: =AN42-AO42 -> 0 | AR42: =AP42-AQ42 -> 0 | AS42: 0 | AT42: =AR42-AS42 -> 0 | AU42: 0 | AV42: =AT42-AU42 -> 0 | AW42: 0 | AX42: =AV42-AW42 -> 0 | AY42: 0 | AZ42: =AX42-AY42 -> 0 | BB42: =AY42+AW42+AU42+AS42+AQ42+AO42+AM42+AK42+AI42+AG42+AE42+AC42+AA42+Y42+W42+U42+S42+Q42+O42+M42+K42 -> 4 | BC42: =$BB42*D42 -> 0 | BD42: =BC42*F42 -> 0 | BE42: =BB42*G42 -> 0 | BF42: =$BB42*E42 -> 4 | BG42: =$BB42*H42 -> 0
C43: Création de la vue globale | D43: 0.25 | E43: =E40 -> 0.75 | F43: 0 | G43: 0 | H43: 0 | I43: 5 | J43: =I43 -> 5 | K43: 1 | L43: =J43-K43 -> 4 | M43: 1 | N43: =L43-M43 -> 3 | O43: 0 | P43: =N43-O43 -> 3 | Q43: 0 | R43: =P43-Q43 -> 3 | S43: 1 | T43: =R43-S43 -> 2 | U43: 0 | V43: =T43-U43 -> 2 | W43: 0 | X43: =V43-W43 -> 2 | Y43: 0 | Z43: =X43-Y43 -> 2 | AA43: 0 | AB43: =Z43-AA43 -> 2 | AC43: 0 | AD43: =AB43-AC43 -> 2 | AE43: 1 | AF43: 3 | AG43: 0 | AH43: =AF43-AG43 -> 3 | AI43: 0 | AJ43: =AH43-AI43 -> 3 | AK43: 0 | AL43: =AJ43-AK43 -> 3 | AM43: 0 | AN43: =AL43-AM43 -> 3 | AO43: 0 | AP43: =AN43-AO43 -> 3 | AQ43: 0 | AR43: =AP43-AQ43 -> 3 | AS43: 3 | AT43: =AR43-AS43 -> 0 | AU43: 0 | AV43: 1 | AW43: 1 | AX43: =AV43-AW43 -> 0 | AY43: 0 | AZ43: =AX43-AY43 -> 0 | BB43: =AY43+AW43+AU43+AS43+AQ43+AO43+AM43+AK43+AI43+AG43+AE43+AC43+AA43+Y43+W43+U43+S43+Q43+O43+M43+K43 -> 8 | BC43: =$BB43*D43 -> 2 | BD43: =BC43*F43 -> 0 | BE43: =BB43*G43 -> 0 | BF43: =$BB43*E43 -> 6 | BG43: =$BB43*H43 -> 0
...

Sheet team
A1: Prénom | B1: Nom | C1: email | D1: nickname
A2: Oryna | B2: Kubarieva | C2: kubarieva.oryna@courrier.uqam.ca | D2: =A2 -> Oryna
A3: Aziz | B3: Thiam | C3: thiam.demba_aziz@courrier.uqam.ca | D3: =A3 -> Aziz
A4: Joana | B4: Munyaneza | C4: munyaneza_mutunge.ursule_joana@courrier.uqam.ca | D4: =A4 -> Joana
A5: Kenny | B5: Kenfack | C5: kenfack_nandjou.steve_marvyn@courrier.uqam.ca | D5: =A5 -> Kenny
A6: Romuald | B6: Sokoujou | C6: kenfack_nandjou.steve_marvyn@courrier.uqam.ca | D6: =A6 -> Romuald
